<?xml version="1.0" ?>
<sdf version="1.9">
  <!-- Define a simple rover model -->
    <model name='rover_blue' canonical_link='chassis'>
        <static>false</static>
        <!-- Position of the rover in the world
        <pose>0 0 0 0 0 0</pose> -->
        
        <!-- Chassis (main body) of the rover -->
        <link name='chassis'>
            <pose relative_to='__model__'>0.5 0 0.4 0 0 0</pose>
            
            <!-- Inertial properties for physics simulation -->
            <inertial>
                <mass>1.14395</mass>
                <inertia>
                    <ixx>0.095329</ixx>
                    <ixy>0</ixy>
                    <ixz>0</ixz>
                    <iyy>0.381317</iyy>
                    <iyz>0</iyz>
                    <izz>0.476646</izz>
                </inertia>
            </inertial>
            
            <!-- Visual representation of the chassis -->
            <visual name='visual'>
                <geometry>
                    <box>
                        <!-- Chassis dimensions -->
                        <size>2.0 1.0 0.5</size> 
                    </box>
                </geometry>
                <material> <!-- Color of the chassis (Blue) -->
                    <ambient>0.0 0.0 1.0 1</ambient>
                    <diffuse>0.0 0.0 1.0 1</diffuse>
                    <specular>0.0 0.0 1.0 1</specular>
                </material>
            </visual>
            
            <!-- Collision properties for physics simulation -->
            <collision name='collision'>
                <geometry>
                    <box>
                        <!-- Same size as visual -->
                        <size>2.0 1.0 0.5</size> 
                    </box>
                </geometry>
            </collision>
        </link>

        <!-- The left wheel link: -->
        <link name='left_wheel'>
            <!-- Back (-x) and left (+y) position -->
            <!-- The wheel is a cylinder rotated 90 deg 
            around the Roll axis -->
            <pose relative_to="chassis">
                -0.5 0.6 0 -1.5707 0 0</pose>
            <inertial>
                <mass>1</mass>
                <inertia>
                    <ixx>0.043333</ixx>
                    <ixy>0</ixy>
                    <ixz>0</ixz>
                    <iyy>0.043333</iyy>
                    <iyz>0</iyz>
                    <izz>0.08</izz>
                </inertia>
            </inertial>
            <visual name='visual'>
                <geometry>
                    <cylinder>
                        <radius>0.4</radius>
                        <length>0.2</length>
                    </cylinder>
                </geometry>
                <material>
                    <!-- Red -->
                    <ambient>1.0 0.0 0.0 1</ambient>
                    <diffuse>1.0 0.0 0.0 1</diffuse>
                    <specular>1.0 0.0 0.0 1</specular>
                </material>
            </visual>
            <collision name='collision'>
            <!-- Same as visual -->
                <geometry>
                    <cylinder>
                        <radius>0.4</radius>
                        <length>0.2</length>
                    </cylinder>
                </geometry>
            </collision>
        </link>

        <!--The right wheel is the same as the left wheel 
        but with different position-->
        <link name='right_wheel'>
            <!-- Back (-x) and right (-y) position -->
            <pose relative_to="chassis"> -0.5 -0.6 0 -1.5707 0 0</pose> 
            <inertial>
                <mass>1</mass>
                <inertia>
                    <ixx>0.043333</ixx>
                    <ixy>0</ixy>
                    <ixz>0</ixz>
                    <iyy>0.043333</iyy>
                    <iyz>0</iyz>
                    <izz>0.08</izz>
                </inertia>
            </inertial>
            <visual name='visual'>
                <geometry>
                    <cylinder>
                        <radius>0.4</radius>
                        <length>0.2</length>
                    </cylinder>
                </geometry>
                <material>
                    <ambient>1.0 0.0 0.0 1</ambient>
                    <diffuse>1.0 0.0 0.0 1</diffuse>
                    <specular>1.0 0.0 0.0 1</specular>
                </material>
            </visual>
            <collision name='collision'>
                <geometry>
                    <cylinder>
                        <radius>0.4</radius>
                        <length>0.2</length>
                    </cylinder>
                </geometry>
            </collision>
        </link>

        <!-- For convenience, we define a new frame 
        for the caster wheel -->
        <frame name="caster_frame" attached_to='chassis'>
            <!-- Front (+x) and below (-z) -->
            <pose>0.8 0 -0.2 0 0 0</pose> 
        </frame>
        <!--caster wheel-->
        <link name='caster'>
            <pose relative_to='caster_frame'/>
            <inertial>
                <mass>1</mass>
                <inertia>
                    <ixx>0.016</ixx>
                    <ixy>0</ixy>
                    <ixz>0</ixz>
                    <iyy>0.016</iyy>
                    <iyz>0</iyz>
                    <izz>0.016</izz>
                </inertia>
            </inertial>
            <visual name='visual'>
                <geometry>
                    <!-- Note: the caster wheel is a sphere, 
                    not a cylinder -->
                    <sphere>
                        <radius>0.2</radius>
                    </sphere>
                </geometry>
                <material>
                    <ambient>0.0 1 0.0 1</ambient>
                    <diffuse>0.0 1 0.0 1</diffuse>
                    <specular>0.0 1 0.0 1</specular>
                </material>
            </visual>
            <collision name='collision'>
                <geometry>
                    <sphere>
                        <radius>0.2</radius>
                    </sphere>
                </geometry>
            </collision>
        </link>

        <joint name='left_wheel_joint' type='revolute'>
            <pose relative_to='left_wheel'/>
            <parent>chassis</parent>
            <child>left_wheel</child>
            <axis>
                <!--can be defined as any frame or even 
                arbitrary frames-->
                <xyz expressed_in='__model__'>0 1 0</xyz> 
                <limit>
                    <!--negative infinity-->
                    <lower>-1.79769e+308</lower>    
                    <!--positive infinity-->
                    <upper>1.79769e+308</upper>     
                </limit>
            </axis>
        </joint>

        <joint name='right_wheel_joint' type='revolute'>
            <pose relative_to='right_wheel'/>
            <parent>chassis</parent>
            <child>right_wheel</child>
            <axis>
                <xyz expressed_in='__model__'>0 1 0</xyz>
                <limit>
                    <!--negative infinity-->
                    <lower>-1.79769e+308</lower>    
                    <!--positive infinity-->
                    <upper>1.79769e+308</upper>     
                </limit>
            </axis>
        </joint>

        <joint name='caster_wheel' type='ball'>
            <parent>chassis</parent>
            <child>caster</child>
        </joint>

        <plugin
            filename="libignition-gazebo-diff-drive-system.so"
            name="ignition::gazebo::systems::DiffDrive">
            <left_joint>left_wheel_joint</left_joint>
            <right_joint>right_wheel_joint</right_joint>
            <wheel_separation>1.2</wheel_separation> <!-- (-0.6 to 0.6) -->
            <wheel_radius>0.4</wheel_radius>       <!-- Cylinder radius -->
            <odom_publish_frequency>1</odom_publish_frequency>
            <topic>rover_blue_cmd_vel</topic>
        </plugin>

        <plugin 
            filename="libignition-gazebo-pose-publisher-system.so"
            name="ignition::gazebo::systems::PosePublisher">
            <publish_link_pose>false</publish_link_pose> <!-- Don't publish link pose -->
            <publish_nested_model_pose>true</publish_nested_model_pose> <!-- Publish nested model pose -->
            <update_frequency>1</update_frequency> 
        </plugin>

    </model>
</sdf>
